Traceback (most recent call last):
  File "/home/lyupo/Work/Python3/projects/python-project-lvl3/page_loader/page.py", line 37, in download
    res = requests.get(page)
  File "/home/lyupo/Work/Python3/projects/python-project-lvl3/.venv/lib/python3.6/site-packages/requests/api.py", line 76, in get
    return request('get', url, params=params, **kwargs)
  File "/home/lyupo/Work/Python3/projects/python-project-lvl3/.venv/lib/python3.6/site-packages/requests/api.py", line 61, in request
    return session.request(method=method, url=url, **kwargs)
  File "/home/lyupo/Work/Python3/projects/python-project-lvl3/.venv/lib/python3.6/site-packages/requests/sessions.py", line 530, in request
    resp = self.send(prep, **send_kwargs)
  File "/home/lyupo/Work/Python3/projects/python-project-lvl3/.venv/lib/python3.6/site-packages/requests/sessions.py", line 637, in send
    adapter = self.get_adapter(url=request.url)
  File "/home/lyupo/Work/Python3/projects/python-project-lvl3/.venv/lib/python3.6/site-packages/requests/sessions.py", line 730, in get_adapter
    raise InvalidSchema("No connection adapters were found for {!r}".format(url))
requests.exceptions.InvalidSchema: No connection adapters were found for 'hcp://pythonjobs.github.io'

The above exception was the direct cause of the following exception:

Traceback (most recent call last):
  File "/home/lyupo/Work/Python3/projects/python-project-lvl3/page_loader/scripts/page_loader.py", line 23, in main
    page.download(namespace.page, namespace.output)
  File "/home/lyupo/Work/Python3/projects/python-project-lvl3/page_loader/page.py", line 43, in download
    raise error.RequestError() from e
page_loader.error.RequestError
Traceback (most recent call last):
  File "/home/lyupo/Work/Python3/projects/python-project-lvl3/page_loader/page.py", line 37, in download
    res = requests.get(page)
  File "/home/lyupo/Work/Python3/projects/python-project-lvl3/.venv/lib/python3.6/site-packages/requests/api.py", line 76, in get
    return request('get', url, params=params, **kwargs)
  File "/home/lyupo/Work/Python3/projects/python-project-lvl3/.venv/lib/python3.6/site-packages/requests/api.py", line 61, in request
    return session.request(method=method, url=url, **kwargs)
  File "/home/lyupo/Work/Python3/projects/python-project-lvl3/.venv/lib/python3.6/site-packages/requests/sessions.py", line 530, in request
    resp = self.send(prep, **send_kwargs)
  File "/home/lyupo/Work/Python3/projects/python-project-lvl3/.venv/lib/python3.6/site-packages/requests/sessions.py", line 637, in send
    adapter = self.get_adapter(url=request.url)
  File "/home/lyupo/Work/Python3/projects/python-project-lvl3/.venv/lib/python3.6/site-packages/requests/sessions.py", line 730, in get_adapter
    raise InvalidSchema("No connection adapters were found for {!r}".format(url))
requests.exceptions.InvalidSchema: No connection adapters were found for 'hcp://pythonjobs.github.io'

The above exception was the direct cause of the following exception:

Traceback (most recent call last):
  File "/home/lyupo/Work/Python3/projects/python-project-lvl3/page_loader/scripts/page_loader.py", line 23, in main
    page.download(namespace.page, namespace.output)
  File "/home/lyupo/Work/Python3/projects/python-project-lvl3/page_loader/page.py", line 43, in download
    raise error.RequestError() from e
page_loader.error.RequestError
Traceback (most recent call last):
  File "/home/lyupo/Work/Python3/projects/python-project-lvl3/.venv/lib/python3.6/site-packages/urllib3/connection.py", line 160, in _new_conn
    (self._dns_host, self.port), self.timeout, **extra_kw
  File "/home/lyupo/Work/Python3/projects/python-project-lvl3/.venv/lib/python3.6/site-packages/urllib3/util/connection.py", line 61, in create_connection
    for res in socket.getaddrinfo(host, port, family, socket.SOCK_STREAM):
  File "/usr/lib/python3.6/socket.py", line 745, in getaddrinfo
    for res in _socket.getaddrinfo(host, port, family, type, proto, flags):
socket.gaierror: [Errno -2] Name or service not known

During handling of the above exception, another exception occurred:

Traceback (most recent call last):
  File "/home/lyupo/Work/Python3/projects/python-project-lvl3/.venv/lib/python3.6/site-packages/urllib3/connectionpool.py", line 677, in urlopen
    chunked=chunked,
  File "/home/lyupo/Work/Python3/projects/python-project-lvl3/.venv/lib/python3.6/site-packages/urllib3/connectionpool.py", line 381, in _make_request
    self._validate_conn(conn)
  File "/home/lyupo/Work/Python3/projects/python-project-lvl3/.venv/lib/python3.6/site-packages/urllib3/connectionpool.py", line 978, in _validate_conn
    conn.connect()
  File "/home/lyupo/Work/Python3/projects/python-project-lvl3/.venv/lib/python3.6/site-packages/urllib3/connection.py", line 309, in connect
    conn = self._new_conn()
  File "/home/lyupo/Work/Python3/projects/python-project-lvl3/.venv/lib/python3.6/site-packages/urllib3/connection.py", line 172, in _new_conn
    self, "Failed to establish a new connection: %s" % e
urllib3.exceptions.NewConnectionError: <urllib3.connection.HTTPSConnection object at 0x7f3c933e5eb8>: Failed to establish a new connection: [Errno -2] Name or service not known

During handling of the above exception, another exception occurred:

Traceback (most recent call last):
  File "/home/lyupo/Work/Python3/projects/python-project-lvl3/.venv/lib/python3.6/site-packages/requests/adapters.py", line 449, in send
    timeout=timeout
  File "/home/lyupo/Work/Python3/projects/python-project-lvl3/.venv/lib/python3.6/site-packages/urllib3/connectionpool.py", line 727, in urlopen
    method, url, error=e, _pool=self, _stacktrace=sys.exc_info()[2]
  File "/home/lyupo/Work/Python3/projects/python-project-lvl3/.venv/lib/python3.6/site-packages/urllib3/util/retry.py", line 446, in increment
    raise MaxRetryError(_pool, url, error or ResponseError(cause))
urllib3.exceptions.MaxRetryError: HTTPSConnectionPool(host='pythonjobs.githlub.io', port=443): Max retries exceeded with url: / (Caused by NewConnectionError('<urllib3.connection.HTTPSConnection object at 0x7f3c933e5eb8>: Failed to establish a new connection: [Errno -2] Name or service not known',))

During handling of the above exception, another exception occurred:

Traceback (most recent call last):
  File "/home/lyupo/Work/Python3/projects/python-project-lvl3/page_loader/page.py", line 37, in download
    res = requests.get(page)
  File "/home/lyupo/Work/Python3/projects/python-project-lvl3/.venv/lib/python3.6/site-packages/requests/api.py", line 76, in get
    return request('get', url, params=params, **kwargs)
  File "/home/lyupo/Work/Python3/projects/python-project-lvl3/.venv/lib/python3.6/site-packages/requests/api.py", line 61, in request
    return session.request(method=method, url=url, **kwargs)
  File "/home/lyupo/Work/Python3/projects/python-project-lvl3/.venv/lib/python3.6/site-packages/requests/sessions.py", line 530, in request
    resp = self.send(prep, **send_kwargs)
  File "/home/lyupo/Work/Python3/projects/python-project-lvl3/.venv/lib/python3.6/site-packages/requests/sessions.py", line 643, in send
    r = adapter.send(request, **kwargs)
  File "/home/lyupo/Work/Python3/projects/python-project-lvl3/.venv/lib/python3.6/site-packages/requests/adapters.py", line 516, in send
    raise ConnectionError(e, request=request)
requests.exceptions.ConnectionError: HTTPSConnectionPool(host='pythonjobs.githlub.io', port=443): Max retries exceeded with url: / (Caused by NewConnectionError('<urllib3.connection.HTTPSConnection object at 0x7f3c933e5eb8>: Failed to establish a new connection: [Errno -2] Name or service not known',))

The above exception was the direct cause of the following exception:

Traceback (most recent call last):
  File "/home/lyupo/Work/Python3/projects/python-project-lvl3/page_loader/scripts/page_loader.py", line 23, in main
    page.download(namespace.page, namespace.output)
  File "/home/lyupo/Work/Python3/projects/python-project-lvl3/page_loader/page.py", line 40, in download
    raise error.ConnectionError() from e
page_loader.error.ConnectionError
Traceback (most recent call last):
  File "/home/lyupo/Work/Python3/projects/python-project-lvl3/.venv/lib/python3.6/site-packages/urllib3/connection.py", line 160, in _new_conn
    (self._dns_host, self.port), self.timeout, **extra_kw
  File "/home/lyupo/Work/Python3/projects/python-project-lvl3/.venv/lib/python3.6/site-packages/urllib3/util/connection.py", line 61, in create_connection
    for res in socket.getaddrinfo(host, port, family, socket.SOCK_STREAM):
  File "/usr/lib/python3.6/socket.py", line 745, in getaddrinfo
    for res in _socket.getaddrinfo(host, port, family, type, proto, flags):
socket.gaierror: [Errno -2] Name or service not known

During handling of the above exception, another exception occurred:

Traceback (most recent call last):
  File "/home/lyupo/Work/Python3/projects/python-project-lvl3/.venv/lib/python3.6/site-packages/urllib3/connectionpool.py", line 677, in urlopen
    chunked=chunked,
  File "/home/lyupo/Work/Python3/projects/python-project-lvl3/.venv/lib/python3.6/site-packages/urllib3/connectionpool.py", line 381, in _make_request
    self._validate_conn(conn)
  File "/home/lyupo/Work/Python3/projects/python-project-lvl3/.venv/lib/python3.6/site-packages/urllib3/connectionpool.py", line 978, in _validate_conn
    conn.connect()
  File "/home/lyupo/Work/Python3/projects/python-project-lvl3/.venv/lib/python3.6/site-packages/urllib3/connection.py", line 309, in connect
    conn = self._new_conn()
  File "/home/lyupo/Work/Python3/projects/python-project-lvl3/.venv/lib/python3.6/site-packages/urllib3/connection.py", line 172, in _new_conn
    self, "Failed to establish a new connection: %s" % e
urllib3.exceptions.NewConnectionError: <urllib3.connection.HTTPSConnection object at 0x7ff03a74d160>: Failed to establish a new connection: [Errno -2] Name or service not known

During handling of the above exception, another exception occurred:

Traceback (most recent call last):
  File "/home/lyupo/Work/Python3/projects/python-project-lvl3/.venv/lib/python3.6/site-packages/requests/adapters.py", line 449, in send
    timeout=timeout
  File "/home/lyupo/Work/Python3/projects/python-project-lvl3/.venv/lib/python3.6/site-packages/urllib3/connectionpool.py", line 727, in urlopen
    method, url, error=e, _pool=self, _stacktrace=sys.exc_info()[2]
  File "/home/lyupo/Work/Python3/projects/python-project-lvl3/.venv/lib/python3.6/site-packages/urllib3/util/retry.py", line 446, in increment
    raise MaxRetryError(_pool, url, error or ResponseError(cause))
urllib3.exceptions.MaxRetryError: HTTPSConnectionPool(host='pythonjobs.githlub.io', port=443): Max retries exceeded with url: / (Caused by NewConnectionError('<urllib3.connection.HTTPSConnection object at 0x7ff03a74d160>: Failed to establish a new connection: [Errno -2] Name or service not known',))

During handling of the above exception, another exception occurred:

Traceback (most recent call last):
  File "/home/lyupo/Work/Python3/projects/python-project-lvl3/page_loader/page.py", line 37, in download
    res = requests.get(page)
  File "/home/lyupo/Work/Python3/projects/python-project-lvl3/.venv/lib/python3.6/site-packages/requests/api.py", line 76, in get
    return request('get', url, params=params, **kwargs)
  File "/home/lyupo/Work/Python3/projects/python-project-lvl3/.venv/lib/python3.6/site-packages/requests/api.py", line 61, in request
    return session.request(method=method, url=url, **kwargs)
  File "/home/lyupo/Work/Python3/projects/python-project-lvl3/.venv/lib/python3.6/site-packages/requests/sessions.py", line 530, in request
    resp = self.send(prep, **send_kwargs)
  File "/home/lyupo/Work/Python3/projects/python-project-lvl3/.venv/lib/python3.6/site-packages/requests/sessions.py", line 643, in send
    r = adapter.send(request, **kwargs)
  File "/home/lyupo/Work/Python3/projects/python-project-lvl3/.venv/lib/python3.6/site-packages/requests/adapters.py", line 516, in send
    raise ConnectionError(e, request=request)
requests.exceptions.ConnectionError: HTTPSConnectionPool(host='pythonjobs.githlub.io', port=443): Max retries exceeded with url: / (Caused by NewConnectionError('<urllib3.connection.HTTPSConnection object at 0x7ff03a74d160>: Failed to establish a new connection: [Errno -2] Name or service not known',))

The above exception was the direct cause of the following exception:

Traceback (most recent call last):
  File "/home/lyupo/Work/Python3/projects/python-project-lvl3/page_loader/scripts/page_loader.py", line 23, in main
    page.download(namespace.page, namespace.output)
  File "/home/lyupo/Work/Python3/projects/python-project-lvl3/page_loader/page.py", line 41, in download
    raise error.ConnectionError() from e
page_loader.error.ConnectionError
Traceback (most recent call last):
  File "/home/lyupo/Work/Python3/projects/python-project-lvl3/page_loader/scripts/page_loader.py", line 23, in main
    page.download(namespace.page, namespace.output)
  File "/home/lyupo/Work/Python3/projects/python-project-lvl3/page_loader/page.py", line 49, in download
    raise error.RequestError()
page_loader.error.RequestError
Traceback (most recent call last):
  File "/home/lyupo/Work/Python3/projects/python-project-lvl3/page_loader/scripts/page_loader.py", line 23, in main
    page.download(namespace.page, namespace.output)
  File "/home/lyupo/Work/Python3/projects/python-project-lvl3/page_loader/page.py", line 49, in download
    raise error.RequestError()
page_loader.error.RequestError
Traceback (most recent call last):
  File "/home/lyupo/Work/Python3/projects/python-project-lvl3/page_loader/scripts/page_loader.py", line 23, in main
    page.download(namespace.page, namespace.output)
  File "/home/lyupo/Work/Python3/projects/python-project-lvl3/page_loader/page.py", line 49, in download
    raise error.RequestError()
page_loader.error.RequestError
Traceback (most recent call last):
  File "/home/lyupo/Work/Python3/projects/python-project-lvl3/.venv/lib/python3.6/site-packages/urllib3/connection.py", line 160, in _new_conn
    (self._dns_host, self.port), self.timeout, **extra_kw
  File "/home/lyupo/Work/Python3/projects/python-project-lvl3/.venv/lib/python3.6/site-packages/urllib3/util/connection.py", line 61, in create_connection
    for res in socket.getaddrinfo(host, port, family, socket.SOCK_STREAM):
  File "/usr/lib/python3.6/socket.py", line 745, in getaddrinfo
    for res in _socket.getaddrinfo(host, port, family, type, proto, flags):
socket.gaierror: [Errno -2] Name or service not known

During handling of the above exception, another exception occurred:

Traceback (most recent call last):
  File "/home/lyupo/Work/Python3/projects/python-project-lvl3/.venv/lib/python3.6/site-packages/urllib3/connectionpool.py", line 677, in urlopen
    chunked=chunked,
  File "/home/lyupo/Work/Python3/projects/python-project-lvl3/.venv/lib/python3.6/site-packages/urllib3/connectionpool.py", line 381, in _make_request
    self._validate_conn(conn)
  File "/home/lyupo/Work/Python3/projects/python-project-lvl3/.venv/lib/python3.6/site-packages/urllib3/connectionpool.py", line 978, in _validate_conn
    conn.connect()
  File "/home/lyupo/Work/Python3/projects/python-project-lvl3/.venv/lib/python3.6/site-packages/urllib3/connection.py", line 309, in connect
    conn = self._new_conn()
  File "/home/lyupo/Work/Python3/projects/python-project-lvl3/.venv/lib/python3.6/site-packages/urllib3/connection.py", line 172, in _new_conn
    self, "Failed to establish a new connection: %s" % e
urllib3.exceptions.NewConnectionError: <urllib3.connection.HTTPSConnection object at 0x7f92c1fd4eb8>: Failed to establish a new connection: [Errno -2] Name or service not known

During handling of the above exception, another exception occurred:

Traceback (most recent call last):
  File "/home/lyupo/Work/Python3/projects/python-project-lvl3/.venv/lib/python3.6/site-packages/requests/adapters.py", line 449, in send
    timeout=timeout
  File "/home/lyupo/Work/Python3/projects/python-project-lvl3/.venv/lib/python3.6/site-packages/urllib3/connectionpool.py", line 727, in urlopen
    method, url, error=e, _pool=self, _stacktrace=sys.exc_info()[2]
  File "/home/lyupo/Work/Python3/projects/python-project-lvl3/.venv/lib/python3.6/site-packages/urllib3/util/retry.py", line 446, in increment
    raise MaxRetryError(_pool, url, error or ResponseError(cause))
urllib3.exceptions.MaxRetryError: HTTPSConnectionPool(host='pythonjobs.github.iso', port=443): Max retries exceeded with url: / (Caused by NewConnectionError('<urllib3.connection.HTTPSConnection object at 0x7f92c1fd4eb8>: Failed to establish a new connection: [Errno -2] Name or service not known',))

During handling of the above exception, another exception occurred:

Traceback (most recent call last):
  File "/home/lyupo/Work/Python3/projects/python-project-lvl3/page_loader/page.py", line 37, in download
    res = requests.get(page)
  File "/home/lyupo/Work/Python3/projects/python-project-lvl3/.venv/lib/python3.6/site-packages/requests/api.py", line 76, in get
    return request('get', url, params=params, **kwargs)
  File "/home/lyupo/Work/Python3/projects/python-project-lvl3/.venv/lib/python3.6/site-packages/requests/api.py", line 61, in request
    return session.request(method=method, url=url, **kwargs)
  File "/home/lyupo/Work/Python3/projects/python-project-lvl3/.venv/lib/python3.6/site-packages/requests/sessions.py", line 530, in request
    resp = self.send(prep, **send_kwargs)
  File "/home/lyupo/Work/Python3/projects/python-project-lvl3/.venv/lib/python3.6/site-packages/requests/sessions.py", line 643, in send
    r = adapter.send(request, **kwargs)
  File "/home/lyupo/Work/Python3/projects/python-project-lvl3/.venv/lib/python3.6/site-packages/requests/adapters.py", line 516, in send
    raise ConnectionError(e, request=request)
requests.exceptions.ConnectionError: HTTPSConnectionPool(host='pythonjobs.github.iso', port=443): Max retries exceeded with url: / (Caused by NewConnectionError('<urllib3.connection.HTTPSConnection object at 0x7f92c1fd4eb8>: Failed to establish a new connection: [Errno -2] Name or service not known',))

The above exception was the direct cause of the following exception:

Traceback (most recent call last):
  File "/home/lyupo/Work/Python3/projects/python-project-lvl3/page_loader/scripts/page_loader.py", line 23, in main
    page.download(namespace.page, namespace.output)
  File "/home/lyupo/Work/Python3/projects/python-project-lvl3/page_loader/page.py", line 41, in download
    raise error.RequestError() from e
page_loader.error.RequestError
Traceback (most recent call last):
  File "/home/lyupo/Work/Python3/projects/python-project-lvl3/.venv/lib/python3.6/site-packages/urllib3/connection.py", line 160, in _new_conn
    (self._dns_host, self.port), self.timeout, **extra_kw
  File "/home/lyupo/Work/Python3/projects/python-project-lvl3/.venv/lib/python3.6/site-packages/urllib3/util/connection.py", line 61, in create_connection
    for res in socket.getaddrinfo(host, port, family, socket.SOCK_STREAM):
  File "/usr/lib/python3.6/socket.py", line 745, in getaddrinfo
    for res in _socket.getaddrinfo(host, port, family, type, proto, flags):
socket.gaierror: [Errno -2] Name or service not known

During handling of the above exception, another exception occurred:

Traceback (most recent call last):
  File "/home/lyupo/Work/Python3/projects/python-project-lvl3/.venv/lib/python3.6/site-packages/urllib3/connectionpool.py", line 677, in urlopen
    chunked=chunked,
  File "/home/lyupo/Work/Python3/projects/python-project-lvl3/.venv/lib/python3.6/site-packages/urllib3/connectionpool.py", line 381, in _make_request
    self._validate_conn(conn)
  File "/home/lyupo/Work/Python3/projects/python-project-lvl3/.venv/lib/python3.6/site-packages/urllib3/connectionpool.py", line 978, in _validate_conn
    conn.connect()
  File "/home/lyupo/Work/Python3/projects/python-project-lvl3/.venv/lib/python3.6/site-packages/urllib3/connection.py", line 309, in connect
    conn = self._new_conn()
  File "/home/lyupo/Work/Python3/projects/python-project-lvl3/.venv/lib/python3.6/site-packages/urllib3/connection.py", line 172, in _new_conn
    self, "Failed to establish a new connection: %s" % e
urllib3.exceptions.NewConnectionError: <urllib3.connection.HTTPSConnection object at 0x7f334926aeb8>: Failed to establish a new connection: [Errno -2] Name or service not known

During handling of the above exception, another exception occurred:

Traceback (most recent call last):
  File "/home/lyupo/Work/Python3/projects/python-project-lvl3/.venv/lib/python3.6/site-packages/requests/adapters.py", line 449, in send
    timeout=timeout
  File "/home/lyupo/Work/Python3/projects/python-project-lvl3/.venv/lib/python3.6/site-packages/urllib3/connectionpool.py", line 727, in urlopen
    method, url, error=e, _pool=self, _stacktrace=sys.exc_info()[2]
  File "/home/lyupo/Work/Python3/projects/python-project-lvl3/.venv/lib/python3.6/site-packages/urllib3/util/retry.py", line 446, in increment
    raise MaxRetryError(_pool, url, error or ResponseError(cause))
urllib3.exceptions.MaxRetryError: HTTPSConnectionPool(host='pythonjobs.github.iso', port=443): Max retries exceeded with url: / (Caused by NewConnectionError('<urllib3.connection.HTTPSConnection object at 0x7f334926aeb8>: Failed to establish a new connection: [Errno -2] Name or service not known',))

During handling of the above exception, another exception occurred:

Traceback (most recent call last):
  File "/home/lyupo/Work/Python3/projects/python-project-lvl3/page_loader/page.py", line 37, in download
    res = requests.get(page)
  File "/home/lyupo/Work/Python3/projects/python-project-lvl3/.venv/lib/python3.6/site-packages/requests/api.py", line 76, in get
    return request('get', url, params=params, **kwargs)
  File "/home/lyupo/Work/Python3/projects/python-project-lvl3/.venv/lib/python3.6/site-packages/requests/api.py", line 61, in request
    return session.request(method=method, url=url, **kwargs)
  File "/home/lyupo/Work/Python3/projects/python-project-lvl3/.venv/lib/python3.6/site-packages/requests/sessions.py", line 530, in request
    resp = self.send(prep, **send_kwargs)
  File "/home/lyupo/Work/Python3/projects/python-project-lvl3/.venv/lib/python3.6/site-packages/requests/sessions.py", line 643, in send
    r = adapter.send(request, **kwargs)
  File "/home/lyupo/Work/Python3/projects/python-project-lvl3/.venv/lib/python3.6/site-packages/requests/adapters.py", line 516, in send
    raise ConnectionError(e, request=request)
requests.exceptions.ConnectionError: HTTPSConnectionPool(host='pythonjobs.github.iso', port=443): Max retries exceeded with url: / (Caused by NewConnectionError('<urllib3.connection.HTTPSConnection object at 0x7f334926aeb8>: Failed to establish a new connection: [Errno -2] Name or service not known',))

The above exception was the direct cause of the following exception:

Traceback (most recent call last):
  File "/home/lyupo/Work/Python3/projects/python-project-lvl3/page_loader/scripts/page_loader.py", line 23, in main
    page.download(namespace.page, namespace.output)
  File "/home/lyupo/Work/Python3/projects/python-project-lvl3/page_loader/page.py", line 41, in download
    raise error.RequestError() from e
page_loader.error.RequestError
Traceback (most recent call last):
  File "/home/lyupo/Work/Python3/projects/python-project-lvl3/.venv/lib/python3.6/site-packages/urllib3/connection.py", line 160, in _new_conn
    (self._dns_host, self.port), self.timeout, **extra_kw
  File "/home/lyupo/Work/Python3/projects/python-project-lvl3/.venv/lib/python3.6/site-packages/urllib3/util/connection.py", line 61, in create_connection
    for res in socket.getaddrinfo(host, port, family, socket.SOCK_STREAM):
  File "/usr/lib/python3.6/socket.py", line 745, in getaddrinfo
    for res in _socket.getaddrinfo(host, port, family, type, proto, flags):
socket.gaierror: [Errno -2] Name or service not known

During handling of the above exception, another exception occurred:

Traceback (most recent call last):
  File "/home/lyupo/Work/Python3/projects/python-project-lvl3/.venv/lib/python3.6/site-packages/urllib3/connectionpool.py", line 677, in urlopen
    chunked=chunked,
  File "/home/lyupo/Work/Python3/projects/python-project-lvl3/.venv/lib/python3.6/site-packages/urllib3/connectionpool.py", line 381, in _make_request
    self._validate_conn(conn)
  File "/home/lyupo/Work/Python3/projects/python-project-lvl3/.venv/lib/python3.6/site-packages/urllib3/connectionpool.py", line 978, in _validate_conn
    conn.connect()
  File "/home/lyupo/Work/Python3/projects/python-project-lvl3/.venv/lib/python3.6/site-packages/urllib3/connection.py", line 309, in connect
    conn = self._new_conn()
  File "/home/lyupo/Work/Python3/projects/python-project-lvl3/.venv/lib/python3.6/site-packages/urllib3/connection.py", line 172, in _new_conn
    self, "Failed to establish a new connection: %s" % e
urllib3.exceptions.NewConnectionError: <urllib3.connection.HTTPSConnection object at 0x7f0abb85b438>: Failed to establish a new connection: [Errno -2] Name or service not known

During handling of the above exception, another exception occurred:

Traceback (most recent call last):
  File "/home/lyupo/Work/Python3/projects/python-project-lvl3/.venv/lib/python3.6/site-packages/requests/adapters.py", line 449, in send
    timeout=timeout
  File "/home/lyupo/Work/Python3/projects/python-project-lvl3/.venv/lib/python3.6/site-packages/urllib3/connectionpool.py", line 727, in urlopen
    method, url, error=e, _pool=self, _stacktrace=sys.exc_info()[2]
  File "/home/lyupo/Work/Python3/projects/python-project-lvl3/.venv/lib/python3.6/site-packages/urllib3/util/retry.py", line 446, in increment
    raise MaxRetryError(_pool, url, error or ResponseError(cause))
urllib3.exceptions.MaxRetryError: HTTPSConnectionPool(host='pythonjobs.github.io', port=443): Max retries exceeded with url: / (Caused by NewConnectionError('<urllib3.connection.HTTPSConnection object at 0x7f0abb85b438>: Failed to establish a new connection: [Errno -2] Name or service not known',))

During handling of the above exception, another exception occurred:

Traceback (most recent call last):
  File "/home/lyupo/Work/Python3/projects/python-project-lvl3/page_loader/link.py", line 38, in download
    res = requests.get(page)
  File "/home/lyupo/Work/Python3/projects/python-project-lvl3/.venv/lib/python3.6/site-packages/requests/api.py", line 76, in get
    return request('get', url, params=params, **kwargs)
  File "/home/lyupo/Work/Python3/projects/python-project-lvl3/.venv/lib/python3.6/site-packages/requests/api.py", line 61, in request
    return session.request(method=method, url=url, **kwargs)
  File "/home/lyupo/Work/Python3/projects/python-project-lvl3/.venv/lib/python3.6/site-packages/requests/sessions.py", line 530, in request
    resp = self.send(prep, **send_kwargs)
  File "/home/lyupo/Work/Python3/projects/python-project-lvl3/.venv/lib/python3.6/site-packages/requests/sessions.py", line 643, in send
    r = adapter.send(request, **kwargs)
  File "/home/lyupo/Work/Python3/projects/python-project-lvl3/.venv/lib/python3.6/site-packages/requests/adapters.py", line 516, in send
    raise ConnectionError(e, request=request)
requests.exceptions.ConnectionError: HTTPSConnectionPool(host='pythonjobs.github.io', port=443): Max retries exceeded with url: / (Caused by NewConnectionError('<urllib3.connection.HTTPSConnection object at 0x7f0abb85b438>: Failed to establish a new connection: [Errno -2] Name or service not known',))

The above exception was the direct cause of the following exception:

Traceback (most recent call last):
  File "/home/lyupo/Work/Python3/projects/python-project-lvl3/page_loader/scripts/page_loader.py", line 23, in main
    link.download(namespace.page, namespace.output)
  File "/home/lyupo/Work/Python3/projects/python-project-lvl3/page_loader/link.py", line 42, in download
    raise error.RequestError() from e
page_loader.error.RequestError
Traceback (most recent call last):
  File "/home/lyupo/Work/Python3/projects/python-project-lvl3/.venv/lib/python3.6/site-packages/urllib3/connection.py", line 160, in _new_conn
    (self._dns_host, self.port), self.timeout, **extra_kw
  File "/home/lyupo/Work/Python3/projects/python-project-lvl3/.venv/lib/python3.6/site-packages/urllib3/util/connection.py", line 61, in create_connection
    for res in socket.getaddrinfo(host, port, family, socket.SOCK_STREAM):
  File "/usr/lib/python3.6/socket.py", line 745, in getaddrinfo
    for res in _socket.getaddrinfo(host, port, family, type, proto, flags):
socket.gaierror: [Errno -2] Name or service not known

During handling of the above exception, another exception occurred:

Traceback (most recent call last):
  File "/home/lyupo/Work/Python3/projects/python-project-lvl3/.venv/lib/python3.6/site-packages/urllib3/connectionpool.py", line 677, in urlopen
    chunked=chunked,
  File "/home/lyupo/Work/Python3/projects/python-project-lvl3/.venv/lib/python3.6/site-packages/urllib3/connectionpool.py", line 381, in _make_request
    self._validate_conn(conn)
  File "/home/lyupo/Work/Python3/projects/python-project-lvl3/.venv/lib/python3.6/site-packages/urllib3/connectionpool.py", line 978, in _validate_conn
    conn.connect()
  File "/home/lyupo/Work/Python3/projects/python-project-lvl3/.venv/lib/python3.6/site-packages/urllib3/connection.py", line 309, in connect
    conn = self._new_conn()
  File "/home/lyupo/Work/Python3/projects/python-project-lvl3/.venv/lib/python3.6/site-packages/urllib3/connection.py", line 172, in _new_conn
    self, "Failed to establish a new connection: %s" % e
urllib3.exceptions.NewConnectionError: <urllib3.connection.HTTPSConnection object at 0x7fd0da09b6d8>: Failed to establish a new connection: [Errno -2] Name or service not known

During handling of the above exception, another exception occurred:

Traceback (most recent call last):
  File "/home/lyupo/Work/Python3/projects/python-project-lvl3/.venv/lib/python3.6/site-packages/requests/adapters.py", line 449, in send
    timeout=timeout
  File "/home/lyupo/Work/Python3/projects/python-project-lvl3/.venv/lib/python3.6/site-packages/urllib3/connectionpool.py", line 727, in urlopen
    method, url, error=e, _pool=self, _stacktrace=sys.exc_info()[2]
  File "/home/lyupo/Work/Python3/projects/python-project-lvl3/.venv/lib/python3.6/site-packages/urllib3/util/retry.py", line 446, in increment
    raise MaxRetryError(_pool, url, error or ResponseError(cause))
urllib3.exceptions.MaxRetryError: HTTPSConnectionPool(host='pythonjobs.github.io', port=443): Max retries exceeded with url: / (Caused by NewConnectionError('<urllib3.connection.HTTPSConnection object at 0x7fd0da09b6d8>: Failed to establish a new connection: [Errno -2] Name or service not known',))

During handling of the above exception, another exception occurred:

Traceback (most recent call last):
  File "/home/lyupo/Work/Python3/projects/python-project-lvl3/page_loader/text.py", line 12, in download
    res = requests.get(page)
  File "/home/lyupo/Work/Python3/projects/python-project-lvl3/.venv/lib/python3.6/site-packages/requests/api.py", line 76, in get
    return request('get', url, params=params, **kwargs)
  File "/home/lyupo/Work/Python3/projects/python-project-lvl3/.venv/lib/python3.6/site-packages/requests/api.py", line 61, in request
    return session.request(method=method, url=url, **kwargs)
  File "/home/lyupo/Work/Python3/projects/python-project-lvl3/.venv/lib/python3.6/site-packages/requests/sessions.py", line 530, in request
    resp = self.send(prep, **send_kwargs)
  File "/home/lyupo/Work/Python3/projects/python-project-lvl3/.venv/lib/python3.6/site-packages/requests/sessions.py", line 643, in send
    r = adapter.send(request, **kwargs)
  File "/home/lyupo/Work/Python3/projects/python-project-lvl3/.venv/lib/python3.6/site-packages/requests/adapters.py", line 516, in send
    raise ConnectionError(e, request=request)
requests.exceptions.ConnectionError: HTTPSConnectionPool(host='pythonjobs.github.io', port=443): Max retries exceeded with url: / (Caused by NewConnectionError('<urllib3.connection.HTTPSConnection object at 0x7fd0da09b6d8>: Failed to establish a new connection: [Errno -2] Name or service not known',))

The above exception was the direct cause of the following exception:

Traceback (most recent call last):
  File "/home/lyupo/Work/Python3/projects/python-project-lvl3/page_loader/scripts/page_loader.py", line 23, in main
    page.download(namespace.page, namespace.output)
  File "/home/lyupo/Work/Python3/projects/python-project-lvl3/page_loader/page.py", line 36, in download
    res = text.download(page)
  File "/home/lyupo/Work/Python3/projects/python-project-lvl3/page_loader/text.py", line 16, in download
    raise error.RequestError() from e
page_loader.error.RequestError
